into the shop module
Watching for file changes with StatReloader
into the shop module
finding the user object for the id 2
user object found for the id 2
finding the user object for the id 2
user object found for the id 2
finding the user object for the id 1
user object found for the id 1
C:\Users\Admin\Desktop\python-training\pythonminiproject\e_product\e_product_comparison\serializers.py changed, reloading.
Watching for file changes with StatReloader
into the shop module
C:\Users\Admin\Desktop\python-training\pythonminiproject\e_product\e_product_comparison\serializers.py changed, reloading.
Watching for file changes with StatReloader
into the shop module
Internal Server Error: /api/v1/shop-product/
Traceback (most recent call last):
  File "C:\Users\Admin\AppData\Local\Programs\Python\Python311\Lib\site-packages\django\core\handlers\exception.py", line 55, in inner
    response = get_response(request)
               ^^^^^^^^^^^^^^^^^^^^^
  File "C:\Users\Admin\AppData\Local\Programs\Python\Python311\Lib\site-packages\django\core\handlers\base.py", line 197, in _get_response
    response = wrapped_callback(request, *callback_args, **callback_kwargs)
               ^^^^^^^^^^^^^^^^^^^^^^^^^^^^^^^^^^^^^^^^^^^^^^^^^^^^^^^^^^^^
  File "C:\Users\Admin\AppData\Local\Programs\Python\Python311\Lib\site-packages\django\views\decorators\csrf.py", line 54, in wrapped_view
    return view_func(*args, **kwargs)
           ^^^^^^^^^^^^^^^^^^^^^^^^^^
  File "C:\Users\Admin\AppData\Local\Programs\Python\Python311\Lib\site-packages\rest_framework\viewsets.py", line 125, in view
    return self.dispatch(request, *args, **kwargs)
           ^^^^^^^^^^^^^^^^^^^^^^^^^^^^^^^^^^^^^^^
  File "C:\Users\Admin\AppData\Local\Programs\Python\Python311\Lib\site-packages\rest_framework\views.py", line 509, in dispatch
    response = self.handle_exception(exc)
               ^^^^^^^^^^^^^^^^^^^^^^^^^^
  File "C:\Users\Admin\AppData\Local\Programs\Python\Python311\Lib\site-packages\rest_framework\views.py", line 469, in handle_exception
    self.raise_uncaught_exception(exc)
  File "C:\Users\Admin\AppData\Local\Programs\Python\Python311\Lib\site-packages\rest_framework\views.py", line 480, in raise_uncaught_exception
    raise exc
  File "C:\Users\Admin\AppData\Local\Programs\Python\Python311\Lib\site-packages\rest_framework\views.py", line 506, in dispatch
    response = handler(request, *args, **kwargs)
               ^^^^^^^^^^^^^^^^^^^^^^^^^^^^^^^^^
  File "C:\Users\Admin\Desktop\python-training\pythonminiproject\e_product\e_product_comparison\views.py", line 141, in create
    shop_product_serializer.is_valid(raise_exception=True)
  File "C:\Users\Admin\AppData\Local\Programs\Python\Python311\Lib\site-packages\rest_framework\serializers.py", line 227, in is_valid
    self._validated_data = self.run_validation(self.initial_data)
                           ^^^^^^^^^^^^^^^^^^^^^^^^^^^^^^^^^^^^^^
  File "C:\Users\Admin\AppData\Local\Programs\Python\Python311\Lib\site-packages\rest_framework\serializers.py", line 426, in run_validation
    value = self.to_internal_value(data)
            ^^^^^^^^^^^^^^^^^^^^^^^^^^^^
  File "C:\Users\Admin\AppData\Local\Programs\Python\Python311\Lib\site-packages\rest_framework\serializers.py", line 485, in to_internal_value
    validated_value = validate_method(validated_value)
                      ^^^^^^^^^^^^^^^^^^^^^^^^^^^^^^^^
TypeError: ShopProductSerializer.validate_vendor_price() missing 2 required positional arguments: 'offer_percentage' and 'vendor_price'
C:\Users\Admin\Desktop\python-training\pythonminiproject\e_product\e_product_comparison\serializers.py changed, reloading.
Watching for file changes with StatReloader
into the shop module
C:\Users\Admin\Desktop\python-training\pythonminiproject\e_product\e_product_comparison\views.py changed, reloading.
Watching for file changes with StatReloader
into the shop module
C:\Users\Admin\Desktop\python-training\pythonminiproject\e_product\e_product_comparison\views.py changed, reloading.
Watching for file changes with StatReloader
C:\Users\Admin\Desktop\python-training\pythonminiproject\e_product\e_product_comparison\views.py changed, reloading.
Watching for file changes with StatReloader
into the shop module
Invalid vendor price for the offer percentage
Internal Server Error: /api/v1/shop-product/
Traceback (most recent call last):
  File "C:\Users\Admin\AppData\Local\Programs\Python\Python311\Lib\site-packages\django\core\handlers\exception.py", line 55, in inner
    response = get_response(request)
               ^^^^^^^^^^^^^^^^^^^^^
  File "C:\Users\Admin\AppData\Local\Programs\Python\Python311\Lib\site-packages\django\core\handlers\base.py", line 197, in _get_response
    response = wrapped_callback(request, *callback_args, **callback_kwargs)
               ^^^^^^^^^^^^^^^^^^^^^^^^^^^^^^^^^^^^^^^^^^^^^^^^^^^^^^^^^^^^
  File "C:\Users\Admin\AppData\Local\Programs\Python\Python311\Lib\site-packages\django\views\decorators\csrf.py", line 54, in wrapped_view
    return view_func(*args, **kwargs)
           ^^^^^^^^^^^^^^^^^^^^^^^^^^
  File "C:\Users\Admin\AppData\Local\Programs\Python\Python311\Lib\site-packages\rest_framework\viewsets.py", line 125, in view
    return self.dispatch(request, *args, **kwargs)
           ^^^^^^^^^^^^^^^^^^^^^^^^^^^^^^^^^^^^^^^
  File "C:\Users\Admin\AppData\Local\Programs\Python\Python311\Lib\site-packages\rest_framework\views.py", line 511, in dispatch
    self.response = self.finalize_response(request, response, *args, **kwargs)
                    ^^^^^^^^^^^^^^^^^^^^^^^^^^^^^^^^^^^^^^^^^^^^^^^^^^^^^^^^^^
  File "C:\Users\Admin\AppData\Local\Programs\Python\Python311\Lib\site-packages\rest_framework\views.py", line 423, in finalize_response
    assert isinstance(response, HttpResponseBase), (
AssertionError: Expected a `Response`, `HttpResponse` or `HttpStreamingResponse` to be returned from the view, but received a `<class 'NoneType'>`
C:\Users\Admin\Desktop\python-training\pythonminiproject\e_product\e_product_comparison\views.py changed, reloading.
Watching for file changes with StatReloader
into the shop module
Invalid vendor price for the offer percentage
Internal Server Error: /api/v1/shop-product/
Traceback (most recent call last):
  File "C:\Users\Admin\Desktop\python-training\pythonminiproject\e_product\e_product_comparison\views.py", line 150, in create
    if valid_offer(actual_price=actual_price, offer_percentage=offer, vendor_price=vendor_price):
       ^^^^^^^^^^^^^^^^^^^^^^^^^^^^^^^^^^^^^^^^^^^^^^^^^^^^^^^^^^^^^^^^^^^^^^^^^^^^^^^^^^^^^^^^^
  File "C:\Users\Admin\Desktop\python-training\pythonminiproject\e_product\e_product_comparison\views.py", line 135, in valid_offer
    raise InvalidValue('Enter a valid amount')
e_product_comparison.custom_exception.InvalidValue: Enter a valid amount

During handling of the above exception, another exception occurred:

Traceback (most recent call last):
  File "C:\Users\Admin\AppData\Local\Programs\Python\Python311\Lib\site-packages\django\core\handlers\exception.py", line 55, in inner
    response = get_response(request)
               ^^^^^^^^^^^^^^^^^^^^^
  File "C:\Users\Admin\AppData\Local\Programs\Python\Python311\Lib\site-packages\django\core\handlers\base.py", line 197, in _get_response
    response = wrapped_callback(request, *callback_args, **callback_kwargs)
               ^^^^^^^^^^^^^^^^^^^^^^^^^^^^^^^^^^^^^^^^^^^^^^^^^^^^^^^^^^^^
  File "C:\Users\Admin\AppData\Local\Programs\Python\Python311\Lib\site-packages\django\views\decorators\csrf.py", line 54, in wrapped_view
    return view_func(*args, **kwargs)
           ^^^^^^^^^^^^^^^^^^^^^^^^^^
  File "C:\Users\Admin\AppData\Local\Programs\Python\Python311\Lib\site-packages\rest_framework\viewsets.py", line 125, in view
    return self.dispatch(request, *args, **kwargs)
           ^^^^^^^^^^^^^^^^^^^^^^^^^^^^^^^^^^^^^^^
  File "C:\Users\Admin\AppData\Local\Programs\Python\Python311\Lib\site-packages\rest_framework\views.py", line 509, in dispatch
    response = self.handle_exception(exc)
               ^^^^^^^^^^^^^^^^^^^^^^^^^^
  File "C:\Users\Admin\AppData\Local\Programs\Python\Python311\Lib\site-packages\rest_framework\views.py", line 469, in handle_exception
    self.raise_uncaught_exception(exc)
  File "C:\Users\Admin\AppData\Local\Programs\Python\Python311\Lib\site-packages\rest_framework\views.py", line 480, in raise_uncaught_exception
    raise exc
  File "C:\Users\Admin\AppData\Local\Programs\Python\Python311\Lib\site-packages\rest_framework\views.py", line 506, in dispatch
    response = handler(request, *args, **kwargs)
               ^^^^^^^^^^^^^^^^^^^^^^^^^^^^^^^^^
  File "C:\Users\Admin\Desktop\python-training\pythonminiproject\e_product\e_product_comparison\views.py", line 154, in create
    raise InvalidValue('Invalid price was provided by the vendor')
e_product_comparison.custom_exception.InvalidValue: Invalid price was provided by the vendor
Entering the user creation method
Bad Request: /api/v1/user/
C:\Users\Admin\Desktop\python-training\pythonminiproject\e_product\e_product_comparison\serializers.py changed, reloading.
Watching for file changes with StatReloader
into the shop module
Entering the user creation method
Bad Request: /api/v1/user/
Internal Server Error: /api/v1/shop-product/
Traceback (most recent call last):
  File "C:\Users\Admin\AppData\Local\Programs\Python\Python311\Lib\site-packages\django\core\handlers\exception.py", line 55, in inner
    response = get_response(request)
               ^^^^^^^^^^^^^^^^^^^^^
  File "C:\Users\Admin\AppData\Local\Programs\Python\Python311\Lib\site-packages\django\core\handlers\base.py", line 197, in _get_response
    response = wrapped_callback(request, *callback_args, **callback_kwargs)
               ^^^^^^^^^^^^^^^^^^^^^^^^^^^^^^^^^^^^^^^^^^^^^^^^^^^^^^^^^^^^
  File "C:\Users\Admin\AppData\Local\Programs\Python\Python311\Lib\site-packages\django\views\decorators\csrf.py", line 54, in wrapped_view
    return view_func(*args, **kwargs)
           ^^^^^^^^^^^^^^^^^^^^^^^^^^
  File "C:\Users\Admin\AppData\Local\Programs\Python\Python311\Lib\site-packages\rest_framework\viewsets.py", line 125, in view
    return self.dispatch(request, *args, **kwargs)
           ^^^^^^^^^^^^^^^^^^^^^^^^^^^^^^^^^^^^^^^
  File "C:\Users\Admin\AppData\Local\Programs\Python\Python311\Lib\site-packages\rest_framework\views.py", line 509, in dispatch
    response = self.handle_exception(exc)
               ^^^^^^^^^^^^^^^^^^^^^^^^^^
  File "C:\Users\Admin\AppData\Local\Programs\Python\Python311\Lib\site-packages\rest_framework\views.py", line 469, in handle_exception
    self.raise_uncaught_exception(exc)
  File "C:\Users\Admin\AppData\Local\Programs\Python\Python311\Lib\site-packages\rest_framework\views.py", line 480, in raise_uncaught_exception
    raise exc
  File "C:\Users\Admin\AppData\Local\Programs\Python\Python311\Lib\site-packages\rest_framework\views.py", line 506, in dispatch
    response = handler(request, *args, **kwargs)
               ^^^^^^^^^^^^^^^^^^^^^^^^^^^^^^^^^
  File "C:\Users\Admin\Desktop\python-training\pythonminiproject\e_product\e_product_comparison\views.py", line 157, in create
    shop_product_serializer.is_valid(raise_exception=True)
  File "C:\Users\Admin\AppData\Local\Programs\Python\Python311\Lib\site-packages\rest_framework\serializers.py", line 227, in is_valid
    self._validated_data = self.run_validation(self.initial_data)
                           ^^^^^^^^^^^^^^^^^^^^^^^^^^^^^^^^^^^^^^
  File "C:\Users\Admin\AppData\Local\Programs\Python\Python311\Lib\site-packages\rest_framework\serializers.py", line 426, in run_validation
    value = self.to_internal_value(data)
            ^^^^^^^^^^^^^^^^^^^^^^^^^^^^
  File "C:\Users\Admin\AppData\Local\Programs\Python\Python311\Lib\site-packages\rest_framework\serializers.py", line 479, in to_internal_value
    for field in fields:
  File "C:\Users\Admin\AppData\Local\Programs\Python\Python311\Lib\site-packages\rest_framework\serializers.py", line 362, in _writable_fields
    for field in self.fields.values():
                 ^^^^^^^^^^^
  File "C:\Users\Admin\AppData\Local\Programs\Python\Python311\Lib\site-packages\django\utils\functional.py", line 57, in __get__
    res = instance.__dict__[self.name] = self.func(instance)
                                         ^^^^^^^^^^^^^^^^^^^
  File "C:\Users\Admin\AppData\Local\Programs\Python\Python311\Lib\site-packages\rest_framework\serializers.py", line 357, in fields
    fields[key] = value
    ~~~~~~^^^^^
  File "C:\Users\Admin\AppData\Local\Programs\Python\Python311\Lib\site-packages\rest_framework\utils\serializer_helpers.py", line 169, in __setitem__
    field.bind(field_name=key, parent=self.serializer)
  File "C:\Users\Admin\AppData\Local\Programs\Python\Python311\Lib\site-packages\rest_framework\fields.py", line 367, in bind
    assert self.source != field_name, (
           ^^^^^^^^^^^^^^^^^^^^^^^^^
AssertionError: It is redundant to specify `source='actual_price'` on field 'FloatField' in serializer 'ShopProductSerializer', because it is the same as the field name. Remove the `source` keyword argument.
C:\Users\Admin\Desktop\python-training\pythonminiproject\e_product\e_product_comparison\serializers.py changed, reloading.
Watching for file changes with StatReloader
into the shop module
Internal Server Error: /api/v1/shop-product/
Traceback (most recent call last):
  File "C:\Users\Admin\AppData\Local\Programs\Python\Python311\Lib\site-packages\django\db\backends\utils.py", line 89, in _execute
    return self.cursor.execute(sql, params)
           ^^^^^^^^^^^^^^^^^^^^^^^^^^^^^^^^
psycopg2.errors.NotNullViolation: null value in column "vendor_price" of relation "e_product_comparison_shopproduct" violates not-null constraint
DETAIL:  Failing row contains (3, 25000, 15, null, t, 2023-01-05 11:04:12.604878+00, 2023-01-05 11:04:12.604878+00, 1, 1, 1, null, 1).


The above exception was the direct cause of the following exception:

Traceback (most recent call last):
  File "C:\Users\Admin\AppData\Local\Programs\Python\Python311\Lib\site-packages\django\core\handlers\exception.py", line 55, in inner
    response = get_response(request)
               ^^^^^^^^^^^^^^^^^^^^^
  File "C:\Users\Admin\AppData\Local\Programs\Python\Python311\Lib\site-packages\django\core\handlers\base.py", line 197, in _get_response
    response = wrapped_callback(request, *callback_args, **callback_kwargs)
               ^^^^^^^^^^^^^^^^^^^^^^^^^^^^^^^^^^^^^^^^^^^^^^^^^^^^^^^^^^^^
  File "C:\Users\Admin\AppData\Local\Programs\Python\Python311\Lib\site-packages\django\views\decorators\csrf.py", line 54, in wrapped_view
    return view_func(*args, **kwargs)
           ^^^^^^^^^^^^^^^^^^^^^^^^^^
  File "C:\Users\Admin\AppData\Local\Programs\Python\Python311\Lib\site-packages\rest_framework\viewsets.py", line 125, in view
    return self.dispatch(request, *args, **kwargs)
           ^^^^^^^^^^^^^^^^^^^^^^^^^^^^^^^^^^^^^^^
  File "C:\Users\Admin\AppData\Local\Programs\Python\Python311\Lib\site-packages\rest_framework\views.py", line 509, in dispatch
    response = self.handle_exception(exc)
               ^^^^^^^^^^^^^^^^^^^^^^^^^^
  File "C:\Users\Admin\AppData\Local\Programs\Python\Python311\Lib\site-packages\rest_framework\views.py", line 469, in handle_exception
    self.raise_uncaught_exception(exc)
  File "C:\Users\Admin\AppData\Local\Programs\Python\Python311\Lib\site-packages\rest_framework\views.py", line 480, in raise_uncaught_exception
    raise exc
  File "C:\Users\Admin\AppData\Local\Programs\Python\Python311\Lib\site-packages\rest_framework\views.py", line 506, in dispatch
    response = handler(request, *args, **kwargs)
               ^^^^^^^^^^^^^^^^^^^^^^^^^^^^^^^^^
  File "C:\Users\Admin\Desktop\python-training\pythonminiproject\e_product\e_product_comparison\views.py", line 158, in create
    shop_product_serializer.save(created_by=created_by)
  File "C:\Users\Admin\AppData\Local\Programs\Python\Python311\Lib\site-packages\rest_framework\serializers.py", line 212, in save
    self.instance = self.create(validated_data)
                    ^^^^^^^^^^^^^^^^^^^^^^^^^^^
  File "C:\Users\Admin\Desktop\python-training\pythonminiproject\e_product\e_product_comparison\serializers.py", line 136, in create
    return ShopProduct.objects.create(**validated_data)
           ^^^^^^^^^^^^^^^^^^^^^^^^^^^^^^^^^^^^^^^^^^^^
  File "C:\Users\Admin\AppData\Local\Programs\Python\Python311\Lib\site-packages\django\db\models\manager.py", line 85, in manager_method
    return getattr(self.get_queryset(), name)(*args, **kwargs)
           ^^^^^^^^^^^^^^^^^^^^^^^^^^^^^^^^^^^^^^^^^^^^^^^^^^^
  File "C:\Users\Admin\AppData\Local\Programs\Python\Python311\Lib\site-packages\django\db\models\query.py", line 671, in create
    obj.save(force_insert=True, using=self.db)
  File "C:\Users\Admin\AppData\Local\Programs\Python\Python311\Lib\site-packages\django\db\models\base.py", line 812, in save
    self.save_base(
  File "C:\Users\Admin\AppData\Local\Programs\Python\Python311\Lib\site-packages\django\db\models\base.py", line 863, in save_base
    updated = self._save_table(
              ^^^^^^^^^^^^^^^^^
  File "C:\Users\Admin\AppData\Local\Programs\Python\Python311\Lib\site-packages\django\db\models\base.py", line 1006, in _save_table
    results = self._do_insert(
              ^^^^^^^^^^^^^^^^
  File "C:\Users\Admin\AppData\Local\Programs\Python\Python311\Lib\site-packages\django\db\models\base.py", line 1047, in _do_insert
    return manager._insert(
           ^^^^^^^^^^^^^^^^
  File "C:\Users\Admin\AppData\Local\Programs\Python\Python311\Lib\site-packages\django\db\models\manager.py", line 85, in manager_method
    return getattr(self.get_queryset(), name)(*args, **kwargs)
           ^^^^^^^^^^^^^^^^^^^^^^^^^^^^^^^^^^^^^^^^^^^^^^^^^^^
  File "C:\Users\Admin\AppData\Local\Programs\Python\Python311\Lib\site-packages\django\db\models\query.py", line 1791, in _insert
    return query.get_compiler(using=using).execute_sql(returning_fields)
           ^^^^^^^^^^^^^^^^^^^^^^^^^^^^^^^^^^^^^^^^^^^^^^^^^^^^^^^^^^^^^
  File "C:\Users\Admin\AppData\Local\Programs\Python\Python311\Lib\site-packages\django\db\models\sql\compiler.py", line 1660, in execute_sql
    cursor.execute(sql, params)
  File "C:\Users\Admin\AppData\Local\Programs\Python\Python311\Lib\site-packages\django\db\backends\utils.py", line 103, in execute
    return super().execute(sql, params)
           ^^^^^^^^^^^^^^^^^^^^^^^^^^^^
  File "C:\Users\Admin\AppData\Local\Programs\Python\Python311\Lib\site-packages\django\db\backends\utils.py", line 67, in execute
    return self._execute_with_wrappers(
           ^^^^^^^^^^^^^^^^^^^^^^^^^^^^
  File "C:\Users\Admin\AppData\Local\Programs\Python\Python311\Lib\site-packages\django\db\backends\utils.py", line 80, in _execute_with_wrappers
    return executor(sql, params, many, context)
           ^^^^^^^^^^^^^^^^^^^^^^^^^^^^^^^^^^^^
  File "C:\Users\Admin\AppData\Local\Programs\Python\Python311\Lib\site-packages\django\db\backends\utils.py", line 84, in _execute
    with self.db.wrap_database_errors:
  File "C:\Users\Admin\AppData\Local\Programs\Python\Python311\Lib\site-packages\django\db\utils.py", line 91, in __exit__
    raise dj_exc_value.with_traceback(traceback) from exc_value
  File "C:\Users\Admin\AppData\Local\Programs\Python\Python311\Lib\site-packages\django\db\backends\utils.py", line 89, in _execute
    return self.cursor.execute(sql, params)
           ^^^^^^^^^^^^^^^^^^^^^^^^^^^^^^^^
django.db.utils.IntegrityError: null value in column "vendor_price" of relation "e_product_comparison_shopproduct" violates not-null constraint
DETAIL:  Failing row contains (3, 25000, 15, null, t, 2023-01-05 11:04:12.604878+00, 2023-01-05 11:04:12.604878+00, 1, 1, 1, null, 1).

C:\Users\Admin\Desktop\python-training\pythonminiproject\e_product\e_product_comparison\serializers.py changed, reloading.
Watching for file changes with StatReloader
into the shop module
C:\Users\Admin\Desktop\python-training\pythonminiproject\e_product\e_product_comparison\views.py changed, reloading.
Watching for file changes with StatReloader
C:\Users\Admin\Desktop\python-training\pythonminiproject\e_product\e_product_comparison\models.py changed, reloading.
Watching for file changes with StatReloader
C:\Users\Admin\Desktop\python-training\pythonminiproject\e_product\e_product_comparison\serializers.py changed, reloading.
Watching for file changes with StatReloader
into the shop module
Entering the user creation method
Bad Request: /api/v1/user/
C:\Users\Admin\Desktop\python-training\pythonminiproject\e_product\e_product_comparison\serializers.py changed, reloading.
Watching for file changes with StatReloader
into the shop module
Entering the user creation method
Bad Request: /api/v1/user/
C:\Users\Admin\Desktop\python-training\pythonminiproject\e_product\e_product_comparison\serializers.py changed, reloading.
Watching for file changes with StatReloader
into the shop module
C:\Users\Admin\Desktop\python-training\pythonminiproject\e_product\e_product_comparison\serializers.py changed, reloading.
Watching for file changes with StatReloader
into the shop module
C:\Users\Admin\Desktop\python-training\pythonminiproject\e_product\e_product_comparison\views.py changed, reloading.
Watching for file changes with StatReloader
into the shop module
C:\Users\Admin\Desktop\python-training\pythonminiproject\e_product\e_product\settings.py changed, reloading.
Watching for file changes with StatReloader
into the shop module
C:\Users\Admin\Desktop\python-training\pythonminiproject\e_product\e_product_comparison\views.py changed, reloading.
Watching for file changes with StatReloader
into the shop module
Invalid vendor price for the offer percentage
Internal Server Error: /api/v1/shop-product/
Traceback (most recent call last):
  File "C:\Users\Admin\Desktop\python-training\pythonminiproject\e_product\e_product_comparison\views.py", line 150, in create
    if valid_offer(actual_price=actual_price, offer_percentage=offer, vendor_price=vendor_price):
       ^^^^^^^^^^^^^^^^^^^^^^^^^^^^^^^^^^^^^^^^^^^^^^^^^^^^^^^^^^^^^^^^^^^^^^^^^^^^^^^^^^^^^^^^^
  File "C:\Users\Admin\Desktop\python-training\pythonminiproject\e_product\e_product_comparison\views.py", line 135, in valid_offer
    raise InvalidValue('Enter a valid amount')
e_product_comparison.custom_exception.InvalidValue: Enter a valid amount

During handling of the above exception, another exception occurred:

Traceback (most recent call last):
  File "C:\Users\Admin\AppData\Local\Programs\Python\Python311\Lib\site-packages\rest_framework\views.py", line 506, in dispatch
    response = handler(request, *args, **kwargs)
               ^^^^^^^^^^^^^^^^^^^^^^^^^^^^^^^^^
  File "C:\Users\Admin\Desktop\python-training\pythonminiproject\e_product\e_product_comparison\views.py", line 155, in create
    return JsonResponse({'message': ex}, status=status.HTTP_400_BAD_REQUEST)
           ^^^^^^^^^^^^^^^^^^^^^^^^^^^^^^^^^^^^^^^^^^^^^^^^^^^^^^^^^^^^^^^^^
  File "C:\Users\Admin\AppData\Local\Programs\Python\Python311\Lib\site-packages\django\http\response.py", line 691, in __init__
    data = json.dumps(data, cls=encoder, **json_dumps_params)
           ^^^^^^^^^^^^^^^^^^^^^^^^^^^^^^^^^^^^^^^^^^^^^^^^^^
  File "C:\Users\Admin\AppData\Local\Programs\Python\Python311\Lib\json\__init__.py", line 238, in dumps
    **kw).encode(obj)
          ^^^^^^^^^^^
  File "C:\Users\Admin\AppData\Local\Programs\Python\Python311\Lib\json\encoder.py", line 200, in encode
    chunks = self.iterencode(o, _one_shot=True)
             ^^^^^^^^^^^^^^^^^^^^^^^^^^^^^^^^^^
  File "C:\Users\Admin\AppData\Local\Programs\Python\Python311\Lib\json\encoder.py", line 258, in iterencode
    return _iterencode(o, 0)
           ^^^^^^^^^^^^^^^^^
  File "C:\Users\Admin\AppData\Local\Programs\Python\Python311\Lib\site-packages\django\core\serializers\json.py", line 106, in default
    return super().default(o)
           ^^^^^^^^^^^^^^^^^^
  File "C:\Users\Admin\AppData\Local\Programs\Python\Python311\Lib\json\encoder.py", line 180, in default
    raise TypeError(f'Object of type {o.__class__.__name__} '
TypeError: Object of type InvalidValue is not JSON serializable

During handling of the above exception, another exception occurred:

Traceback (most recent call last):
  File "C:\Users\Admin\AppData\Local\Programs\Python\Python311\Lib\site-packages\django\utils\module_loading.py", line 30, in import_string
    return cached_import(module_path, class_name)
           ^^^^^^^^^^^^^^^^^^^^^^^^^^^^^^^^^^^^^^
  File "C:\Users\Admin\AppData\Local\Programs\Python\Python311\Lib\site-packages\django\utils\module_loading.py", line 16, in cached_import
    return getattr(module, class_name)
           ^^^^^^^^^^^^^^^^^^^^^^^^^^^
AttributeError: module 'e_product_comparison' has no attribute 'custom_exception_handler'

The above exception was the direct cause of the following exception:

Traceback (most recent call last):
  File "C:\Users\Admin\AppData\Local\Programs\Python\Python311\Lib\site-packages\rest_framework\settings.py", line 177, in import_from_string
    return import_string(val)
           ^^^^^^^^^^^^^^^^^^
  File "C:\Users\Admin\AppData\Local\Programs\Python\Python311\Lib\site-packages\django\utils\module_loading.py", line 32, in import_string
    raise ImportError(
ImportError: Module "e_product_comparison" does not define a "custom_exception_handler" attribute/class

During handling of the above exception, another exception occurred:

Traceback (most recent call last):
  File "C:\Users\Admin\AppData\Local\Programs\Python\Python311\Lib\site-packages\django\core\handlers\exception.py", line 55, in inner
    response = get_response(request)
               ^^^^^^^^^^^^^^^^^^^^^
  File "C:\Users\Admin\AppData\Local\Programs\Python\Python311\Lib\site-packages\django\core\handlers\base.py", line 197, in _get_response
    response = wrapped_callback(request, *callback_args, **callback_kwargs)
               ^^^^^^^^^^^^^^^^^^^^^^^^^^^^^^^^^^^^^^^^^^^^^^^^^^^^^^^^^^^^
  File "C:\Users\Admin\AppData\Local\Programs\Python\Python311\Lib\site-packages\django\views\decorators\csrf.py", line 54, in wrapped_view
    return view_func(*args, **kwargs)
           ^^^^^^^^^^^^^^^^^^^^^^^^^^
  File "C:\Users\Admin\AppData\Local\Programs\Python\Python311\Lib\site-packages\rest_framework\viewsets.py", line 125, in view
    return self.dispatch(request, *args, **kwargs)
           ^^^^^^^^^^^^^^^^^^^^^^^^^^^^^^^^^^^^^^^
  File "C:\Users\Admin\AppData\Local\Programs\Python\Python311\Lib\site-packages\rest_framework\views.py", line 509, in dispatch
    response = self.handle_exception(exc)
               ^^^^^^^^^^^^^^^^^^^^^^^^^^
  File "C:\Users\Admin\AppData\Local\Programs\Python\Python311\Lib\site-packages\rest_framework\views.py", line 463, in handle_exception
    exception_handler = self.get_exception_handler()
                        ^^^^^^^^^^^^^^^^^^^^^^^^^^^^
  File "C:\Users\Admin\AppData\Local\Programs\Python\Python311\Lib\site-packages\rest_framework\views.py", line 298, in get_exception_handler
    return self.settings.EXCEPTION_HANDLER
           ^^^^^^^^^^^^^^^^^^^^^^^^^^^^^^^
  File "C:\Users\Admin\AppData\Local\Programs\Python\Python311\Lib\site-packages\rest_framework\settings.py", line 225, in __getattr__
    val = perform_import(val, attr)
          ^^^^^^^^^^^^^^^^^^^^^^^^^
  File "C:\Users\Admin\AppData\Local\Programs\Python\Python311\Lib\site-packages\rest_framework\settings.py", line 166, in perform_import
    return import_from_string(val, setting_name)
           ^^^^^^^^^^^^^^^^^^^^^^^^^^^^^^^^^^^^^
  File "C:\Users\Admin\AppData\Local\Programs\Python\Python311\Lib\site-packages\rest_framework\settings.py", line 180, in import_from_string
    raise ImportError(msg)
ImportError: Could not import 'e_product_comparison.custom_exception_handler' for API setting 'EXCEPTION_HANDLER'. ImportError: Module "e_product_comparison" does not define a "custom_exception_handler" attribute/class.
C:\Users\Admin\Desktop\python-training\pythonminiproject\e_product\e_product\settings.py changed, reloading.
Watching for file changes with StatReloader
into the shop module
Invalid vendor price for the offer percentage
Internal Server Error: /api/v1/shop-product/
Traceback (most recent call last):
  File "C:\Users\Admin\Desktop\python-training\pythonminiproject\e_product\e_product_comparison\views.py", line 150, in create
    if valid_offer(actual_price=actual_price, offer_percentage=offer, vendor_price=vendor_price):
       ^^^^^^^^^^^^^^^^^^^^^^^^^^^^^^^^^^^^^^^^^^^^^^^^^^^^^^^^^^^^^^^^^^^^^^^^^^^^^^^^^^^^^^^^^
  File "C:\Users\Admin\Desktop\python-training\pythonminiproject\e_product\e_product_comparison\views.py", line 135, in valid_offer
    raise InvalidValue('Enter a valid amount')
e_product_comparison.custom_exception.InvalidValue: Enter a valid amount

During handling of the above exception, another exception occurred:

Traceback (most recent call last):
  File "C:\Users\Admin\AppData\Local\Programs\Python\Python311\Lib\site-packages\rest_framework\views.py", line 506, in dispatch
    response = handler(request, *args, **kwargs)
               ^^^^^^^^^^^^^^^^^^^^^^^^^^^^^^^^^
  File "C:\Users\Admin\Desktop\python-training\pythonminiproject\e_product\e_product_comparison\views.py", line 155, in create
    return JsonResponse({'message': ex}, status=status.HTTP_400_BAD_REQUEST)
           ^^^^^^^^^^^^^^^^^^^^^^^^^^^^^^^^^^^^^^^^^^^^^^^^^^^^^^^^^^^^^^^^^
  File "C:\Users\Admin\AppData\Local\Programs\Python\Python311\Lib\site-packages\django\http\response.py", line 691, in __init__
    data = json.dumps(data, cls=encoder, **json_dumps_params)
           ^^^^^^^^^^^^^^^^^^^^^^^^^^^^^^^^^^^^^^^^^^^^^^^^^^
  File "C:\Users\Admin\AppData\Local\Programs\Python\Python311\Lib\json\__init__.py", line 238, in dumps
    **kw).encode(obj)
          ^^^^^^^^^^^
  File "C:\Users\Admin\AppData\Local\Programs\Python\Python311\Lib\json\encoder.py", line 200, in encode
    chunks = self.iterencode(o, _one_shot=True)
             ^^^^^^^^^^^^^^^^^^^^^^^^^^^^^^^^^^
  File "C:\Users\Admin\AppData\Local\Programs\Python\Python311\Lib\json\encoder.py", line 258, in iterencode
    return _iterencode(o, 0)
           ^^^^^^^^^^^^^^^^^
  File "C:\Users\Admin\AppData\Local\Programs\Python\Python311\Lib\site-packages\django\core\serializers\json.py", line 106, in default
    return super().default(o)
           ^^^^^^^^^^^^^^^^^^
  File "C:\Users\Admin\AppData\Local\Programs\Python\Python311\Lib\json\encoder.py", line 180, in default
    raise TypeError(f'Object of type {o.__class__.__name__} '
TypeError: Object of type InvalidValue is not JSON serializable

During handling of the above exception, another exception occurred:

Traceback (most recent call last):
  File "C:\Users\Admin\AppData\Local\Programs\Python\Python311\Lib\site-packages\rest_framework\settings.py", line 177, in import_from_string
    return import_string(val)
           ^^^^^^^^^^^^^^^^^^
  File "C:\Users\Admin\AppData\Local\Programs\Python\Python311\Lib\site-packages\django\utils\module_loading.py", line 30, in import_string
    return cached_import(module_path, class_name)
           ^^^^^^^^^^^^^^^^^^^^^^^^^^^^^^^^^^^^^^
  File "C:\Users\Admin\AppData\Local\Programs\Python\Python311\Lib\site-packages\django\utils\module_loading.py", line 15, in cached_import
    module = import_module(module_path)
             ^^^^^^^^^^^^^^^^^^^^^^^^^^
  File "C:\Users\Admin\AppData\Local\Programs\Python\Python311\Lib\importlib\__init__.py", line 126, in import_module
    return _bootstrap._gcd_import(name[level:], package, level)
           ^^^^^^^^^^^^^^^^^^^^^^^^^^^^^^^^^^^^^^^^^^^^^^^^^^^^
  File "<frozen importlib._bootstrap>", line 1206, in _gcd_import
  File "<frozen importlib._bootstrap>", line 1178, in _find_and_load
  File "<frozen importlib._bootstrap>", line 1142, in _find_and_load_unlocked
ModuleNotFoundError: No module named 'e_product.e_product_comparison'

During handling of the above exception, another exception occurred:

Traceback (most recent call last):
  File "C:\Users\Admin\AppData\Local\Programs\Python\Python311\Lib\site-packages\django\core\handlers\exception.py", line 55, in inner
    response = get_response(request)
               ^^^^^^^^^^^^^^^^^^^^^
  File "C:\Users\Admin\AppData\Local\Programs\Python\Python311\Lib\site-packages\django\core\handlers\base.py", line 197, in _get_response
    response = wrapped_callback(request, *callback_args, **callback_kwargs)
               ^^^^^^^^^^^^^^^^^^^^^^^^^^^^^^^^^^^^^^^^^^^^^^^^^^^^^^^^^^^^
  File "C:\Users\Admin\AppData\Local\Programs\Python\Python311\Lib\site-packages\django\views\decorators\csrf.py", line 54, in wrapped_view
    return view_func(*args, **kwargs)
           ^^^^^^^^^^^^^^^^^^^^^^^^^^
  File "C:\Users\Admin\AppData\Local\Programs\Python\Python311\Lib\site-packages\rest_framework\viewsets.py", line 125, in view
    return self.dispatch(request, *args, **kwargs)
           ^^^^^^^^^^^^^^^^^^^^^^^^^^^^^^^^^^^^^^^
  File "C:\Users\Admin\AppData\Local\Programs\Python\Python311\Lib\site-packages\rest_framework\views.py", line 509, in dispatch
    response = self.handle_exception(exc)
               ^^^^^^^^^^^^^^^^^^^^^^^^^^
  File "C:\Users\Admin\AppData\Local\Programs\Python\Python311\Lib\site-packages\rest_framework\views.py", line 463, in handle_exception
    exception_handler = self.get_exception_handler()
                        ^^^^^^^^^^^^^^^^^^^^^^^^^^^^
  File "C:\Users\Admin\AppData\Local\Programs\Python\Python311\Lib\site-packages\rest_framework\views.py", line 298, in get_exception_handler
    return self.settings.EXCEPTION_HANDLER
           ^^^^^^^^^^^^^^^^^^^^^^^^^^^^^^^
  File "C:\Users\Admin\AppData\Local\Programs\Python\Python311\Lib\site-packages\rest_framework\settings.py", line 225, in __getattr__
    val = perform_import(val, attr)
          ^^^^^^^^^^^^^^^^^^^^^^^^^
  File "C:\Users\Admin\AppData\Local\Programs\Python\Python311\Lib\site-packages\rest_framework\settings.py", line 166, in perform_import
    return import_from_string(val, setting_name)
           ^^^^^^^^^^^^^^^^^^^^^^^^^^^^^^^^^^^^^
  File "C:\Users\Admin\AppData\Local\Programs\Python\Python311\Lib\site-packages\rest_framework\settings.py", line 180, in import_from_string
    raise ImportError(msg)
ImportError: Could not import 'e_product.e_product_comparison.custom_exception_handler' for API setting 'EXCEPTION_HANDLER'. ModuleNotFoundError: No module named 'e_product.e_product_comparison'.
C:\Users\Admin\Desktop\python-training\pythonminiproject\e_product\e_product\settings.py changed, reloading.
Watching for file changes with StatReloader
into the shop module
Invalid vendor price for the offer percentage
Internal Server Error: /api/v1/shop-product/
Traceback (most recent call last):
  File "C:\Users\Admin\Desktop\python-training\pythonminiproject\e_product\e_product_comparison\views.py", line 150, in create
    if valid_offer(actual_price=actual_price, offer_percentage=offer, vendor_price=vendor_price):
       ^^^^^^^^^^^^^^^^^^^^^^^^^^^^^^^^^^^^^^^^^^^^^^^^^^^^^^^^^^^^^^^^^^^^^^^^^^^^^^^^^^^^^^^^^
  File "C:\Users\Admin\Desktop\python-training\pythonminiproject\e_product\e_product_comparison\views.py", line 135, in valid_offer
    raise InvalidValue('Enter a valid amount')
e_product_comparison.custom_exception.InvalidValue: Enter a valid amount

During handling of the above exception, another exception occurred:

Traceback (most recent call last):
  File "C:\Users\Admin\AppData\Local\Programs\Python\Python311\Lib\site-packages\rest_framework\views.py", line 506, in dispatch
    response = handler(request, *args, **kwargs)
               ^^^^^^^^^^^^^^^^^^^^^^^^^^^^^^^^^
  File "C:\Users\Admin\Desktop\python-training\pythonminiproject\e_product\e_product_comparison\views.py", line 155, in create
    return JsonResponse({'message': ex}, status=status.HTTP_400_BAD_REQUEST)
           ^^^^^^^^^^^^^^^^^^^^^^^^^^^^^^^^^^^^^^^^^^^^^^^^^^^^^^^^^^^^^^^^^
  File "C:\Users\Admin\AppData\Local\Programs\Python\Python311\Lib\site-packages\django\http\response.py", line 691, in __init__
    data = json.dumps(data, cls=encoder, **json_dumps_params)
           ^^^^^^^^^^^^^^^^^^^^^^^^^^^^^^^^^^^^^^^^^^^^^^^^^^
  File "C:\Users\Admin\AppData\Local\Programs\Python\Python311\Lib\json\__init__.py", line 238, in dumps
    **kw).encode(obj)
          ^^^^^^^^^^^
  File "C:\Users\Admin\AppData\Local\Programs\Python\Python311\Lib\json\encoder.py", line 200, in encode
    chunks = self.iterencode(o, _one_shot=True)
             ^^^^^^^^^^^^^^^^^^^^^^^^^^^^^^^^^^
  File "C:\Users\Admin\AppData\Local\Programs\Python\Python311\Lib\json\encoder.py", line 258, in iterencode
    return _iterencode(o, 0)
           ^^^^^^^^^^^^^^^^^
  File "C:\Users\Admin\AppData\Local\Programs\Python\Python311\Lib\site-packages\django\core\serializers\json.py", line 106, in default
    return super().default(o)
           ^^^^^^^^^^^^^^^^^^
  File "C:\Users\Admin\AppData\Local\Programs\Python\Python311\Lib\json\encoder.py", line 180, in default
    raise TypeError(f'Object of type {o.__class__.__name__} '
TypeError: Object of type InvalidValue is not JSON serializable

During handling of the above exception, another exception occurred:

Traceback (most recent call last):
  File "C:\Users\Admin\AppData\Local\Programs\Python\Python311\Lib\site-packages\django\utils\module_loading.py", line 30, in import_string
    return cached_import(module_path, class_name)
           ^^^^^^^^^^^^^^^^^^^^^^^^^^^^^^^^^^^^^^
  File "C:\Users\Admin\AppData\Local\Programs\Python\Python311\Lib\site-packages\django\utils\module_loading.py", line 16, in cached_import
    return getattr(module, class_name)
           ^^^^^^^^^^^^^^^^^^^^^^^^^^^
AttributeError: module 'e_product.utils' has no attribute 'custom_exception_handler'

The above exception was the direct cause of the following exception:

Traceback (most recent call last):
  File "C:\Users\Admin\AppData\Local\Programs\Python\Python311\Lib\site-packages\rest_framework\settings.py", line 177, in import_from_string
    return import_string(val)
           ^^^^^^^^^^^^^^^^^^
  File "C:\Users\Admin\AppData\Local\Programs\Python\Python311\Lib\site-packages\django\utils\module_loading.py", line 32, in import_string
    raise ImportError(
ImportError: Module "e_product.utils" does not define a "custom_exception_handler" attribute/class

During handling of the above exception, another exception occurred:

Traceback (most recent call last):
  File "C:\Users\Admin\AppData\Local\Programs\Python\Python311\Lib\site-packages\django\core\handlers\exception.py", line 55, in inner
    response = get_response(request)
               ^^^^^^^^^^^^^^^^^^^^^
  File "C:\Users\Admin\AppData\Local\Programs\Python\Python311\Lib\site-packages\django\core\handlers\base.py", line 197, in _get_response
    response = wrapped_callback(request, *callback_args, **callback_kwargs)
               ^^^^^^^^^^^^^^^^^^^^^^^^^^^^^^^^^^^^^^^^^^^^^^^^^^^^^^^^^^^^
  File "C:\Users\Admin\AppData\Local\Programs\Python\Python311\Lib\site-packages\django\views\decorators\csrf.py", line 54, in wrapped_view
    return view_func(*args, **kwargs)
           ^^^^^^^^^^^^^^^^^^^^^^^^^^
  File "C:\Users\Admin\AppData\Local\Programs\Python\Python311\Lib\site-packages\rest_framework\viewsets.py", line 125, in view
    return self.dispatch(request, *args, **kwargs)
           ^^^^^^^^^^^^^^^^^^^^^^^^^^^^^^^^^^^^^^^
  File "C:\Users\Admin\AppData\Local\Programs\Python\Python311\Lib\site-packages\rest_framework\views.py", line 509, in dispatch
    response = self.handle_exception(exc)
               ^^^^^^^^^^^^^^^^^^^^^^^^^^
  File "C:\Users\Admin\AppData\Local\Programs\Python\Python311\Lib\site-packages\rest_framework\views.py", line 463, in handle_exception
    exception_handler = self.get_exception_handler()
                        ^^^^^^^^^^^^^^^^^^^^^^^^^^^^
  File "C:\Users\Admin\AppData\Local\Programs\Python\Python311\Lib\site-packages\rest_framework\views.py", line 298, in get_exception_handler
    return self.settings.EXCEPTION_HANDLER
           ^^^^^^^^^^^^^^^^^^^^^^^^^^^^^^^
  File "C:\Users\Admin\AppData\Local\Programs\Python\Python311\Lib\site-packages\rest_framework\settings.py", line 225, in __getattr__
    val = perform_import(val, attr)
          ^^^^^^^^^^^^^^^^^^^^^^^^^
  File "C:\Users\Admin\AppData\Local\Programs\Python\Python311\Lib\site-packages\rest_framework\settings.py", line 166, in perform_import
    return import_from_string(val, setting_name)
           ^^^^^^^^^^^^^^^^^^^^^^^^^^^^^^^^^^^^^
  File "C:\Users\Admin\AppData\Local\Programs\Python\Python311\Lib\site-packages\rest_framework\settings.py", line 180, in import_from_string
    raise ImportError(msg)
ImportError: Could not import 'e_product.utils.custom_exception_handler' for API setting 'EXCEPTION_HANDLER'. ImportError: Module "e_product.utils" does not define a "custom_exception_handler" attribute/class.
C:\Users\Admin\Desktop\python-training\pythonminiproject\e_product\e_product\settings.py changed, reloading.
Watching for file changes with StatReloader
into the shop module
Invalid vendor price for the offer percentage
Internal Server Error: /api/v1/shop-product/
Traceback (most recent call last):
  File "C:\Users\Admin\Desktop\python-training\pythonminiproject\e_product\e_product_comparison\views.py", line 150, in create
    if valid_offer(actual_price=actual_price, offer_percentage=offer, vendor_price=vendor_price):
       ^^^^^^^^^^^^^^^^^^^^^^^^^^^^^^^^^^^^^^^^^^^^^^^^^^^^^^^^^^^^^^^^^^^^^^^^^^^^^^^^^^^^^^^^^
  File "C:\Users\Admin\Desktop\python-training\pythonminiproject\e_product\e_product_comparison\views.py", line 135, in valid_offer
    raise InvalidValue('Enter a valid amount')
e_product_comparison.custom_exception.InvalidValue: Enter a valid amount

During handling of the above exception, another exception occurred:

Traceback (most recent call last):
  File "C:\Users\Admin\AppData\Local\Programs\Python\Python311\Lib\site-packages\django\core\handlers\exception.py", line 55, in inner
    response = get_response(request)
               ^^^^^^^^^^^^^^^^^^^^^
  File "C:\Users\Admin\AppData\Local\Programs\Python\Python311\Lib\site-packages\django\core\handlers\base.py", line 197, in _get_response
    response = wrapped_callback(request, *callback_args, **callback_kwargs)
               ^^^^^^^^^^^^^^^^^^^^^^^^^^^^^^^^^^^^^^^^^^^^^^^^^^^^^^^^^^^^
  File "C:\Users\Admin\AppData\Local\Programs\Python\Python311\Lib\site-packages\django\views\decorators\csrf.py", line 54, in wrapped_view
    return view_func(*args, **kwargs)
           ^^^^^^^^^^^^^^^^^^^^^^^^^^
  File "C:\Users\Admin\AppData\Local\Programs\Python\Python311\Lib\site-packages\rest_framework\viewsets.py", line 125, in view
    return self.dispatch(request, *args, **kwargs)
           ^^^^^^^^^^^^^^^^^^^^^^^^^^^^^^^^^^^^^^^
  File "C:\Users\Admin\AppData\Local\Programs\Python\Python311\Lib\site-packages\rest_framework\views.py", line 509, in dispatch
    response = self.handle_exception(exc)
               ^^^^^^^^^^^^^^^^^^^^^^^^^^
  File "C:\Users\Admin\AppData\Local\Programs\Python\Python311\Lib\site-packages\rest_framework\views.py", line 469, in handle_exception
    self.raise_uncaught_exception(exc)
  File "C:\Users\Admin\AppData\Local\Programs\Python\Python311\Lib\site-packages\rest_framework\views.py", line 480, in raise_uncaught_exception
    raise exc
  File "C:\Users\Admin\AppData\Local\Programs\Python\Python311\Lib\site-packages\rest_framework\views.py", line 506, in dispatch
    response = handler(request, *args, **kwargs)
               ^^^^^^^^^^^^^^^^^^^^^^^^^^^^^^^^^
  File "C:\Users\Admin\Desktop\python-training\pythonminiproject\e_product\e_product_comparison\views.py", line 155, in create
    return JsonResponse({'message': ex}, status=status.HTTP_400_BAD_REQUEST)
           ^^^^^^^^^^^^^^^^^^^^^^^^^^^^^^^^^^^^^^^^^^^^^^^^^^^^^^^^^^^^^^^^^
  File "C:\Users\Admin\AppData\Local\Programs\Python\Python311\Lib\site-packages\django\http\response.py", line 691, in __init__
    data = json.dumps(data, cls=encoder, **json_dumps_params)
           ^^^^^^^^^^^^^^^^^^^^^^^^^^^^^^^^^^^^^^^^^^^^^^^^^^
  File "C:\Users\Admin\AppData\Local\Programs\Python\Python311\Lib\json\__init__.py", line 238, in dumps
    **kw).encode(obj)
          ^^^^^^^^^^^
  File "C:\Users\Admin\AppData\Local\Programs\Python\Python311\Lib\json\encoder.py", line 200, in encode
    chunks = self.iterencode(o, _one_shot=True)
             ^^^^^^^^^^^^^^^^^^^^^^^^^^^^^^^^^^
  File "C:\Users\Admin\AppData\Local\Programs\Python\Python311\Lib\json\encoder.py", line 258, in iterencode
    return _iterencode(o, 0)
           ^^^^^^^^^^^^^^^^^
  File "C:\Users\Admin\AppData\Local\Programs\Python\Python311\Lib\site-packages\django\core\serializers\json.py", line 106, in default
    return super().default(o)
           ^^^^^^^^^^^^^^^^^^
  File "C:\Users\Admin\AppData\Local\Programs\Python\Python311\Lib\json\encoder.py", line 180, in default
    raise TypeError(f'Object of type {o.__class__.__name__} '
TypeError: Object of type InvalidValue is not JSON serializable
C:\Users\Admin\Desktop\python-training\pythonminiproject\e_product\e_product_comparison\views.py changed, reloading.
Watching for file changes with StatReloader
into the shop module
C:\Users\Admin\Desktop\python-training\pythonminiproject\e_product\e_product_comparison\views.py changed, reloading.
Watching for file changes with StatReloader
into the shop module
finding the user object for the id 5
user object found for the id 5
finding the user object for the id 10
Not Found: /api/v1/user/1/
C:\Users\Admin\Desktop\python-training\pythonminiproject\e_product\e_product_comparison\custom_exception.py changed, reloading.
Watching for file changes with StatReloader
into the shop module
finding the user object for the id 10
Not Found: /api/v1/user/1/
C:\Users\Admin\Desktop\python-training\pythonminiproject\e_product\e_product_comparison\views.py changed, reloading.
Watching for file changes with StatReloader
into the shop module
finding the user object for the id 10
Not Found: /api/v1/user/1/
C:\Users\Admin\Desktop\python-training\pythonminiproject\e_product\e_product_comparison\views.py changed, reloading.
Watching for file changes with StatReloader
into the shop module
C:\Users\Admin\Desktop\python-training\pythonminiproject\e_product\e_product_comparison\views.py changed, reloading.
Watching for file changes with StatReloader
into the shop module
C:\Users\Admin\Desktop\python-training\pythonminiproject\e_product\e_product_comparison\views.py changed, reloading.
Watching for file changes with StatReloader
into the shop module
finding the user object for the id 
Not Found: /api/v1/user/10/
finding the user object for the id 
Not Found: /api/v1/user/10/
C:\Users\Admin\Desktop\python-training\pythonminiproject\e_product\e_product_comparison\views.py changed, reloading.
Watching for file changes with StatReloader
into the shop module
finding the user object for the id 
Not Found: /api/v1/user/10/
finding the user object for the id 
user object found for the id 
finding the user object for the id 
Not Found: /api/v1/user/10/
C:\Users\Admin\Desktop\python-training\pythonminiproject\e_product\e_product_comparison\views.py changed, reloading.
Watching for file changes with StatReloader
into the shop module
C:\Users\Admin\Desktop\python-training\pythonminiproject\e_product\e_product\settings.py changed, reloading.
Watching for file changes with StatReloader
into the shop module
finding the user object for the id 
Not Found: /api/v1/user/10/
finding the user object for the id 
user object found for the id 
finding the user object for the id 
Not Found: /api/v1/user/9/
finding the user object for the id 
Not Found: /api/v1/user/7/
finding the user object for the id 
user object found for the id 
finding the user object for the id 
Not Found: /api/v1/user/7/
finding the user object for the id 
user object found for the id 
C:\Users\Admin\Desktop\python-training\pythonminiproject\e_product\e_product_comparison\views.py changed, reloading.
Watching for file changes with StatReloader
into the shop module
finding the user object for the id 
Internal Server Error: /api/v1/user/3/
Traceback (most recent call last):
  File "C:\Users\Admin\AppData\Local\Programs\Python\Python311\Lib\site-packages\django\core\handlers\exception.py", line 55, in inner
    response = get_response(request)
               ^^^^^^^^^^^^^^^^^^^^^
  File "C:\Users\Admin\AppData\Local\Programs\Python\Python311\Lib\site-packages\django\core\handlers\base.py", line 197, in _get_response
    response = wrapped_callback(request, *callback_args, **callback_kwargs)
               ^^^^^^^^^^^^^^^^^^^^^^^^^^^^^^^^^^^^^^^^^^^^^^^^^^^^^^^^^^^^
  File "C:\Users\Admin\AppData\Local\Programs\Python\Python311\Lib\site-packages\django\views\decorators\csrf.py", line 54, in wrapped_view
    return view_func(*args, **kwargs)
           ^^^^^^^^^^^^^^^^^^^^^^^^^^
  File "C:\Users\Admin\AppData\Local\Programs\Python\Python311\Lib\site-packages\rest_framework\viewsets.py", line 125, in view
    return self.dispatch(request, *args, **kwargs)
           ^^^^^^^^^^^^^^^^^^^^^^^^^^^^^^^^^^^^^^^
  File "C:\Users\Admin\AppData\Local\Programs\Python\Python311\Lib\site-packages\rest_framework\views.py", line 509, in dispatch
    response = self.handle_exception(exc)
               ^^^^^^^^^^^^^^^^^^^^^^^^^^
  File "C:\Users\Admin\AppData\Local\Programs\Python\Python311\Lib\site-packages\rest_framework\views.py", line 469, in handle_exception
    self.raise_uncaught_exception(exc)
  File "C:\Users\Admin\AppData\Local\Programs\Python\Python311\Lib\site-packages\rest_framework\views.py", line 480, in raise_uncaught_exception
    raise exc
  File "C:\Users\Admin\AppData\Local\Programs\Python\Python311\Lib\site-packages\rest_framework\views.py", line 506, in dispatch
    response = handler(request, *args, **kwargs)
               ^^^^^^^^^^^^^^^^^^^^^^^^^^^^^^^^^
  File "C:\Users\Admin\Desktop\python-training\pythonminiproject\e_product\e_product_comparison\views.py", line 53, in retrieve
    data = User.objects.get(id=request.user.id)
           ^^^^^^^^^^^^^^^^^^^^^^^^^^^^^^^^^^^^
  File "C:\Users\Admin\AppData\Local\Programs\Python\Python311\Lib\site-packages\django\db\models\manager.py", line 85, in manager_method
    return getattr(self.get_queryset(), name)(*args, **kwargs)
           ^^^^^^^^^^^^^^^^^^^^^^^^^^^^^^^^^^^^^^^^^^^^^^^^^^^
  File "C:\Users\Admin\AppData\Local\Programs\Python\Python311\Lib\site-packages\django\db\models\query.py", line 650, in get
    raise self.model.DoesNotExist(
e_product_comparison.models.User.DoesNotExist: User matching query does not exist.
C:\Users\Admin\Desktop\python-training\pythonminiproject\e_product\e_product_comparison\views.py changed, reloading.
Watching for file changes with StatReloader
into the shop module
C:\Users\Admin\Desktop\python-training\pythonminiproject\e_product\e_product_comparison\views.py changed, reloading.
Watching for file changes with StatReloader
into the shop module
finding the user object for the id 
Internal Server Error: /api/v1/user/3/
Traceback (most recent call last):
  File "C:\Users\Admin\AppData\Local\Programs\Python\Python311\Lib\site-packages\django\core\handlers\exception.py", line 55, in inner
    response = get_response(request)
               ^^^^^^^^^^^^^^^^^^^^^
  File "C:\Users\Admin\AppData\Local\Programs\Python\Python311\Lib\site-packages\django\core\handlers\base.py", line 197, in _get_response
    response = wrapped_callback(request, *callback_args, **callback_kwargs)
               ^^^^^^^^^^^^^^^^^^^^^^^^^^^^^^^^^^^^^^^^^^^^^^^^^^^^^^^^^^^^
  File "C:\Users\Admin\AppData\Local\Programs\Python\Python311\Lib\site-packages\django\views\decorators\csrf.py", line 54, in wrapped_view
    return view_func(*args, **kwargs)
           ^^^^^^^^^^^^^^^^^^^^^^^^^^
  File "C:\Users\Admin\AppData\Local\Programs\Python\Python311\Lib\site-packages\rest_framework\viewsets.py", line 125, in view
    return self.dispatch(request, *args, **kwargs)
           ^^^^^^^^^^^^^^^^^^^^^^^^^^^^^^^^^^^^^^^
  File "C:\Users\Admin\AppData\Local\Programs\Python\Python311\Lib\site-packages\rest_framework\views.py", line 509, in dispatch
    response = self.handle_exception(exc)
               ^^^^^^^^^^^^^^^^^^^^^^^^^^
  File "C:\Users\Admin\AppData\Local\Programs\Python\Python311\Lib\site-packages\rest_framework\views.py", line 469, in handle_exception
    self.raise_uncaught_exception(exc)
  File "C:\Users\Admin\AppData\Local\Programs\Python\Python311\Lib\site-packages\rest_framework\views.py", line 480, in raise_uncaught_exception
    raise exc
  File "C:\Users\Admin\AppData\Local\Programs\Python\Python311\Lib\site-packages\rest_framework\views.py", line 506, in dispatch
    response = handler(request, *args, **kwargs)
               ^^^^^^^^^^^^^^^^^^^^^^^^^^^^^^^^^
  File "C:\Users\Admin\Desktop\python-training\pythonminiproject\e_product\e_product_comparison\views.py", line 55, in retrieve
    data = User.objects.get(id=user.id)
           ^^^^^^^^^^^^^^^^^^^^^^^^^^^^
  File "C:\Users\Admin\AppData\Local\Programs\Python\Python311\Lib\site-packages\django\db\models\manager.py", line 85, in manager_method
    return getattr(self.get_queryset(), name)(*args, **kwargs)
           ^^^^^^^^^^^^^^^^^^^^^^^^^^^^^^^^^^^^^^^^^^^^^^^^^^^
  File "C:\Users\Admin\AppData\Local\Programs\Python\Python311\Lib\site-packages\django\db\models\query.py", line 650, in get
    raise self.model.DoesNotExist(
e_product_comparison.models.User.DoesNotExist: User matching query does not exist.
C:\Users\Admin\Desktop\python-training\pythonminiproject\e_product\e_product_comparison\views.py changed, reloading.
Watching for file changes with StatReloader
into the shop module
finding the user object for the id 
user object found for the id 
C:\Users\Admin\Desktop\python-training\pythonminiproject\e_product\e_product_comparison\views.py changed, reloading.
Watching for file changes with StatReloader
into the shop module
C:\Users\Admin\Desktop\python-training\pythonminiproject\e_product\e_product_comparison\views.py changed, reloading.
Watching for file changes with StatReloader
into the shop module
finding the user object for the id 
user object found for the id 
C:\Users\Admin\Desktop\python-training\pythonminiproject\e_product\e_product_comparison\views.py changed, reloading.
Watching for file changes with StatReloader
into the shop module
finding the user object for the id 
user object found for the id 
finding the user object for the id 
user object found for the id 
finding the user object for the id 
Not Found: /api/v1/user/7/
finding the user object for the id 
user object found for the id 
C:\Users\Admin\Desktop\python-training\pythonminiproject\e_product\e_product_comparison\views.py changed, reloading.
Watching for file changes with StatReloader
into the shop module
finding the user object for the id 
user object found for the id 
finding the user object for the id 
Not Found: /api/v1/user/7/
